Workbook

Sheet Petunjuk
B1: PETUNJUK PENGGUNAAN — Kalkulator Amplop Anggaran Interior Toko
C2: Alat bantu bagi desainer untuk menentukan kisaran anggaran interior yang masuk akal secara bisnis, walaupun data dari klien minim (cukup: kategori usaha, luas, target penjualan per m², masa sewa, lokasi). Tujuannya: menyepakati 'amplop anggaran' SEBELUM mendesain, agar tidak bolak-balik revisi karena budget dipangkas.
B4: LEGENDA WARNA
B5: Contoh isian | C5: KUNING MUDA, teks biru = BOLEH DIISI / DIUBAH (input & parameter).
B6: =1+1 -> 2 | C6: ABU-ABU = RUMUS otomatis. Jangan diketik ulang/dihapus.
B7: Hasil | C7: BIRU MUDA = HASIL UTAMA yang dibawa ke diskusi dengan klien.
B8: SEHAT / SESUAI | C8: Hijau = aman. Kuning = ketat / pas-pasan. Merah = berisiko / anggaran tidak cukup.
B10: ISI SHEET
B11: Petunjuk | C11: Halaman ini.
B12: Kalkulator | C12: Tempat bekerja. Isi bagian 1, hasil muncul otomatis di bagian 2–6.
B13: Parameter | C13: Patokan industri (faktor K, biaya pasar per m², alokasi per elemen, faktor penyesuaian). Boleh diubah jika Anda punya data lebih baik.
B14: Database Proyek | C14: Catatan proyek Anda sendiri untuk mengkalibrasi faktor K dari waktu ke waktu.
B16: LANGKAH PENGGUNAAN
B17: Langkah 1 | C17: Buka sheet Kalkulator. Isi sel kuning di bagian 1. Sel C6–C15 sudah berisi CONTOH — timpa dengan data proyek Anda.
B18: Langkah 2 | C18: Kategori usaha, masa sewa, lokasi, kondisi unit, kota, flagship: klik sel, lalu pilih dari panah ▼ (dropdown).
B19: Langkah 3 | C19: Target penjualan per m² diisi PER BULAN dalam Rupiah penuh (contoh 2500000). Jika klien memberi angka per tahun, bagi 12 terlebih dahulu.
B20: Langkah 4 | C20: Baca bagian 3 'Amplop Anggaran': tiga tingkat konsep Basic / Standard / Signature, lengkap dengan total & per m².
B21: Langkah 5 | C21: Baca bagian 4: apakah anggaran yang LAYAK cukup untuk membayar BIAYA PASAR interior di lokasi tersebut. Jika 'TIDAK CUKUP', sederhanakan konsep atau tanyakan ulang target penjualan ke klien.
B22: Langkah 6 | C22: Baca bagian 5: perkiraan payback. Idealnya SEHAT (≤ 50% masa sewa).
B23: Langkah 7 | C23: Pakai bagian 6 (alokasi per elemen) sebagai batas anggaran tiap elemen desain. Jika nanti budget dipangkas, potong elemen yang paling kecil dampaknya ke penjualan — bukan merombak semua desain.
B24: Langkah 8 | C24: Presentasikan amplop anggaran + ruang lingkup 'interior' ke klien dan minta persetujuan tertulis SEBELUM mulai desain.
B26: CARA KERJA RUMUS (untuk menjelaskan ke klien)
B27: Rumus inti | C27: Anggaran interior = Penjualan per tahun × K
B28: Faktor K | C28: Persentase penjualan setahun yang wajar dipakai untuk interior. Diturunkan dari: (laba operasional toko % − biaya modal stok %) × target payback × porsi interior dari total capex. Usaha bermargin tinggi (F&B, fashion) punya K besar; bermargin tipis/stok besar (minimarket, big-box) K kecil.
B29: Faktor masa sewa | C29: Sewa 5 tahun = patokan (1,00x). Sewa lebih pendek → anggaran harus lebih kecil; lebih panjang → boleh lebih besar.
B30: Faktor flagship | C30: Toko flagship boleh +25%, HANYA bila klien setuju selisihnya dianggap biaya branding.
B31: Cek biaya pasar | C31: Membandingkan anggaran yang layak (sisi bisnis) dengan biaya pasar per m² (sisi biaya) setelah disesuaikan lokasi, kondisi unit, dan kota.
B32: Cek payback | C32: Total capex ≈ anggaran interior ÷ porsi interior. Payback = total capex ÷ laba operasional per tahun. Belum termasuk stok dan masa ramp-up tahun pertama.
B33: K manual | C33: Jika Anda sudah punya K hasil kalibrasi (sheet Database Proyek), isi di Kalkulator!C15. Basic = K −15%, Standard = K, Signature = K +15%.
B35: TIPS MENGHINDARI REVISI
B36: Sepakati ruang lingkup | C36: Pastikan klien setuju apa saja yang termasuk 'interior': MEP/AC, rak & gondola, signage, fasad, furnitur lepas? Ketidakjelasan ruang lingkup adalah sumber revisi paling sering.
B37: Tawarkan 3 tingkat | C37: Basic / Standard / Signature memberi klien pilihan tanpa Anda harus mendesain ulang dari nol.
B38: Kunci cadangan | C38: Jangan hapus baris cadangan (contingency) 5–10%.
B39: Kalibrasi | C39: Setiap proyek selesai, catat di Database Proyek. Setelah ±3 proyek per kategori, pakai K Anda sendiri.
B41: CATATAN PENTING
C42: • Semua angka di sheet Parameter adalah kisaran indikatif (Jabodetabek, kualitas menengah, ±2025–2026), hasil turunan asumsi industri umum — bukan data resmi atau milik merek tertentu.
C43: • Gunakan sebagai titik awal diskusi. Validasi dengan penawaran kontraktor dan data aktual klien.
C44: • Sheet tidak dikunci. Jika ingin melindungi rumus: Review → Protect Sheet (sel kuning sudah bisa dibuka kuncinya terlebih dahulu via Format Cells → Protection → hilangkan centang Locked).

Sheet Kalkulator
B1: KALKULATOR AMPLOP ANGGARAN INTERIOR TOKO
B2: Menentukan kisaran capex interior yang wajar dari: kategori usaha, luas, target penjualan per m², masa sewa, dan lokasi.
B3: Legenda: | C3: Boleh diisi / diubah | D3: Rumus (jangan diubah) | E3: Hasil utama
B5: 1. DATA PROYEK (isi sel kuning)
B6: Nama proyek | C6: Toko Perlengkapan Rumah – Mall Contoh | D6: Bebas, untuk identitas.
B7: Kategori usaha | C7: Perlengkapan rumah & perkakas (big-box) | D7: Pilih dari daftar (klik sel → panah ▼).
B8: Luas toko (m²) | C8: 3000 | D8: Luas area sewa (net lettable area).
B9: Target penjualan per m² per bulan (Rp) | C9: 2500000 | D9: Dari klien. Jika klien memberi per tahun, bagi 12 dulu.
B10: Masa sewa (tahun) | C10: 5 | D10: Pilih 3 / 5 / 7 / 10.
B11: Lokasi | C11: Mall | D11: Mall / Ruko / Bangunan mandiri.
B12: Kondisi unit saat serah terima | C12: Standar serah terima | D12: Standar / Bare shell / Bekas toko.
B13: Kota | C13: Kota besar (Jabodetabek, Surabaya, dll.) | D13: Kota besar / Kota lapis kedua.
B14: Toko flagship? | C14: Tidak | D14: Ya hanya jika klien setuju kelebihan biaya = biaya branding.
B15: K manual (opsional, %) | D15: Kosongkan untuk memakai tabel. Isi jika Anda punya K sendiri (mis. dari sheet Database Proyek).
B17: 2. DASAR PERHITUNGAN (otomatis)
B18: Penjualan per bulan | C18: =C8*C9 -> 7500000000 | D18: Luas × target penjualan per m².
B19: Penjualan per tahun | C19: =C18*12 -> 90000000000 | D19: Dasar perhitungan anggaran.
B20: K minimum (dari tabel) | C20: =INDEX(Parameter!$B$6:$B$14,MATCH($C$7,Parameter!$A$6:$A$14,0)) -> 0.09 | D20: Batas bawah anggaran interior ÷ penjualan setahun.
B21: K maksimum (dari tabel) | C21: =INDEX(Parameter!$C$6:$C$14,MATCH($C$7,Parameter!$A$6:$A$14,0)) -> 0.13 | D21: Batas atas.
B22: Faktor masa sewa | C22: =INDEX(Parameter!$B$33:$B$36,MATCH($C$10,Parameter!$A$33:$A$36,0)) -> 1 | D22: 5 thn = 1,00x (patokan).
B23: Faktor flagship | C23: =INDEX(Parameter!$B$40:$B$41,MATCH($C$14,Parameter!$A$40:$A$41,0)) -> 1 | D23: Tidak = 1,00x.
B24: K terpakai — minimum | C24: =IF($C$15="",C20,$C$15*0.85)*C22*C23 -> 0.09 | D24: Jika K manual diisi: K manual −15%.
B25: K terpakai — maksimum | C25: =IF($C$15="",C21,$C$15*1.15)*C22*C23 -> 0.13 | D25: Jika K manual diisi: K manual +15%.
B27: 3. AMPLOP ANGGARAN INTERIOR (yang LAYAK secara bisnis)
B28: Tingkat konsep | C28: K | D28: Anggaran interior total | E28: Anggaran per m² | F28: Arahan konsep
B29: Basic | C29: =C24 -> 0.09 | D29: =$C$19*C29 -> 8100000000 | E29: =IF($C$8>0,D29/$C$8,0) -> 2700000 | F29: Fungsional, material standar, fokus pada fixture & pencahayaan dasar.
B30: Standard (rekomendasi) | C30: =AVERAGE(C24,C25) -> 0.11 | D30: =$C$19*C30 -> 9900000000 | E30: =IF($C$8>0,D30/$C$8,0) -> 3300000 | F30: Seimbang: investasi di area depan, pencahayaan, signage; hemat di area belakang.
B31: Signature | C31: =C25 -> 0.13 | D31: =$C$19*C31 -> 11700000000 | E31: =IF($C$8>0,D31/$C$8,0) -> 3900000 | F31: Konsep kuat & material lebih baik. Pastikan target penjualan realistis.
B33: 4. CEK KEWAJARAN: apakah anggaran cukup untuk biaya pasar?
B34: Faktor lokasi | C34: =INDEX(Parameter!$B$45:$B$47,MATCH($C$11,Parameter!$A$45:$A$47,0)) -> 1 | D34: Mall = 1,00x (patokan).
B35: Faktor kondisi unit | C35: =INDEX(Parameter!$B$51:$B$53,MATCH($C$12,Parameter!$A$51:$A$53,0)) -> 1
B36: Faktor kota | C36: =INDEX(Parameter!$B$57:$B$58,MATCH($C$13,Parameter!$A$57:$A$58,0)) -> 1
B37: Biaya pasar interior per m² — min | C37: =INDEX(Parameter!$G$6:$G$14,MATCH($C$7,Parameter!$A$6:$A$14,0))*C34*C35*C36 -> 2000000 | D37: Patokan Tabel 1 × semua faktor.
B38: Biaya pasar interior per m² — maks | C38: =INDEX(Parameter!$H$6:$H$14,MATCH($C$7,Parameter!$A$6:$A$14,0))*C34*C35*C36 -> 4000000
B39: Anggaran Standard per m² (dari bagian 3) | C39: =E30 -> 3300000
B40: STATUS | C40: =IF(C39>=C38,"LONGGAR — anggaran di atas biaya pasar. Ruang untuk konsep lebih kuat / material lebih baik.",IF(C39>=C37,"SESUAI — anggaran berada di kisaran biaya pasar. Desain kualitas menengah aman.","TIDAK CUKUP — anggaran di bawah biaya pasar. Sederhanakan spesifikasi, kurangi area yang didesain, atau cek ulang target penjualan.")) -> SESUAI — anggaran berada di kisaran biaya pasar. Desain kualitas menengah aman.
B42: 5. CEK PAYBACK (perkiraan, belum termasuk stok)
B43: EBITDA toko % (dari tabel) | C43: =INDEX(Parameter!$D$6:$D$14,MATCH($C$7,Parameter!$A$6:$A$14,0)) -> 0.1 | D43: Laba operasional toko sebelum penyusutan.
B44: Porsi interior dari total capex | C44: =INDEX(Parameter!$E$6:$E$14,MATCH($C$7,Parameter!$A$6:$A$14,0)) -> 0.65 | D44: Sisanya: peralatan, IT, pra-operasional, dll.
B45: Perkiraan total capex (tingkat Standard) | C45: =IF(C44>0,D30/C44,0) -> 1.5230769e+10 | D45: Anggaran interior ÷ porsi interior.
...

Sheet Parameter
A1: PARAMETER INDUSTRI (rule of thumb)
A2: Sel berwarna kuning boleh diubah sesuai pengalaman/data Anda. Semua angka adalah kisaran indikatif (Jabodetabek, kualitas menengah, ±2025–2026), bukan data resmi.
A4: TABEL 1 — Faktor K dan patokan biaya per kategori
A5: Kategori usaha | B5: K min | C5: K maks | D5: EBITDA toko % | E5: Porsi interior dari total capex | F5: Target payback capex (thn) | G5: Biaya interior pasar min (Rp/m²) | H5: Biaya interior pasar maks (Rp/m²) | I5: Luas tipikal | J5: Keterangan
A6: Kafe / resto (F&B) | B6: 0.18 | C6: 0.3 | D6: 0.175 | E6: 0.6 | F6: 2.5 | G6: 4000000 | H6: 8000000 | I6: 80–200 m² | J6: Dapur & peralatan dihitung terpisah (porsi interior ±60%).
A7: Fashion / aksesoris | B7: 0.2 | C7: 0.35 | D7: 0.15 | E7: 0.85 | F7: 2.5 | G7: 3000000 | H7: 7000000 | I7: 60–300 m² | J7: Interior adalah porsi terbesar capex.
A8: Salon | B8: 0.2 | C8: 0.35 | D8: 0.175 | E8: 0.7 | F8: 3 | G8: 3000000 | H8: 6000000 | I8: 60–150 m²
A9: Klinik kecantikan / kesehatan | B9: 0.2 | C9: 0.35 | D9: 0.2 | E9: 0.45 | F9: 3 | G9: 4000000 | H9: 8000000 | I9: 100–250 m² | J9: Alat medis mahal, porsi interior kecil.
A10: Furnitur & dekorasi rumah (big-box) | B10: 0.1 | C10: 0.16 | D10: 0.1 | E10: 0.75 | F10: 3 | G10: 2500000 | H10: 5000000 | I10: 2.000–8.000 m² | J10: Showroom = alat jual; stok & display besar.
A11: Perlengkapan rumah & perkakas (big-box) | B11: 0.09 | C11: 0.13 | D11: 0.1 | E11: 0.65 | F11: 2.5 | G11: 2000000 | H11: 4000000 | I11: 1.500–5.000 m² | J11: Stok sangat besar (puluhan ribu SKU) mengurangi ruang capex.
A12: Apotek / toko kesehatan | B12: 0.04 | C12: 0.08 | D12: 0.065 | E12: 0.55 | F12: 3 | G12: 1500000 | H12: 3000000 | I12: 50–120 m²
A13: Minimarket / grocery | B13: 0.04 | C13: 0.07 | D13: 0.05 | E13: 0.35 | F13: 3 | G13: 1500000 | H13: 3000000 | I13: 100–250 m² | J13: Rak/chiller dihitung terpisah dari interior.
A14: Elektronik / gadget | B14: 0.04 | C14: 0.09 | D14: 0.05 | E14: 0.75 | F14: 2 | G14: 3000000 | H14: 6000000 | I14: 20–100 m² | J14: Stok besar; nilai juga dari perputaran stok.
A15: K = anggaran interior ÷ penjualan setahun (kondisi toko sudah stabil). K diturunkan dari: (EBITDA% − biaya modal stok%) × target payback × porsi interior.
A18: TABEL 2 — Alokasi anggaran interior per elemen (% dari total)
A19: Kategori usaha | B19: Rak / fixture / furnitur display | C19: Pencahayaan & listrik | D19: Lantai, dinding, plafon | E19: Fasad, signage & penunjuk arah | F19: Zona khusus / area pelanggan | G19: Cadangan (contingency) | H19: Total (harus 100%)
A20: =A6 -> Kafe / resto (F&B) | B20: 0.25 | C20: 0.15 | D20: 0.3 | E20: 0.12 | F20: 0.1 | G20: 0.08 | H20: =SUM(B20:G20) -> 1
A21: =A7 -> Fashion / aksesoris | B21: 0.3 | C21: 0.18 | D21: 0.25 | E21: 0.12 | F21: 0.07 | G21: 0.08 | H21: =SUM(B21:G21) -> 1
A22: =A8 -> Salon | B22: 0.25 | C22: 0.15 | D22: 0.3 | E22: 0.1 | F22: 0.12 | G22: 0.08 | H22: =SUM(B22:G22) -> 1
A23: =A9 -> Klinik kecantikan / kesehatan | B23: 0.2 | C23: 0.15 | D23: 0.3 | E23: 0.1 | F23: 0.17 | G23: 0.08 | H23: =SUM(B23:G23) -> 1
A24: =A10 -> Furnitur & dekorasi rumah (big-box) | B24: 0.32 | C24: 0.18 | D24: 0.24 | E24: 0.1 | F24: 0.08 | G24: 0.08 | H24: =SUM(B24:G24) -> 1
A25: =A11 -> Perlengkapan rumah & perkakas (big-box) | B25: 0.4 | C25: 0.17 | D25: 0.17 | E25: 0.1 | F25: 0.09 | G25: 0.07 | H25: =SUM(B25:G25) -> 1
A26: =A12 -> Apotek / toko kesehatan | B26: 0.35 | C26: 0.15 | D26: 0.25 | E26: 0.1 | F26: 0.07 | G26: 0.08 | H26: =SUM(B26:G26) -> 1
A27: =A13 -> Minimarket / grocery | B27: 0.35 | C27: 0.18 | D27: 0.22 | E27: 0.1 | F27: 0.07 | G27: 0.08 | H27: =SUM(B27:G27) -> 1
A28: =A14 -> Elektronik / gadget | B28: 0.3 | C28: 0.18 | D28: 0.22 | E28: 0.12 | F28: 0.1 | G28: 0.08 | H28: =SUM(B28:G28) -> 1
A31: TABEL 3 — Faktor masa sewa (mengali anggaran yang LAYAK)
A32: Pilihan | B32: Faktor | C32: Sewa lebih panjang = waktu balik modal lebih panjang = anggaran boleh lebih besar.
A33: 3 | B33: 0.7
A34: 5 | B34: 1
A35: 7 | B35: 1.15
A36: 10 | B36: 1.3
A38: TABEL 4 — Faktor flagship (mengali anggaran yang LAYAK)
A39: Pilihan | B39: Faktor | C39: Hanya jika klien setuju kelebihan biaya dianggap biaya branding/promosi.
A40: Tidak | B40: 1
A41: Ya | B41: 1.25
A43: TABEL 5 — Faktor lokasi (mengali BIAYA PASAR per m²)
A44: Pilihan | B44: Faktor | C44: Patokan biaya di Tabel 1 = kondisi mall. Ruko umumnya lebih murah; standalone perlu MEP/fasad lebih banyak.
A45: Mall | B45: 1
A46: Ruko | B46: 0.85
A47: Bangunan mandiri (standalone) | B47: 1.05
...

Sheet Database Proyek
A1: DATABASE PROYEK — kalibrasi faktor K versi Anda sendiri
A2: Catat proyek yang sudah selesai & toko yang sudah beroperasi ±1 tahun. Sel kuning diisi; kolom abu dihitung otomatis. Baris 5 adalah CONTOH — hapus/timpa dengan data Anda.
A4: Nama proyek | B4: Kategori usaha | C4: Tahun | D4: Lokasi | E4: Luas (m²) | F4: Penjualan aktual per m² per bulan (Rp) | G4: Biaya interior aktual (Rp) | H4: Penjualan per tahun (Rp) | I4: K aktual | J4: Biaya interior per m² (Rp) | K4: Catatan | M4: Ringkasan per kategori | N4: Jumlah proyek | O4: Rata-rata K Anda | P4: K tabel (tengah)
A5: CONTOH – Toko Perkakas Kota A | B5: Perlengkapan rumah & perkakas (big-box) | C5: 2025 | D5: Mall | E5: 2800 | F5: 2300000 | G5: 8400000000 | H5: =IF(OR(E5="",F5=""),"",E5*F5*12) -> 77280000000 | I5: =IF(OR(G5="",H5="",H5=0),"",G5/H5) -> 0.10869565 | J5: =IF(OR(G5="",E5="",E5=0),"",G5/E5) -> 3000000 | K5: Contoh fiktif, hapus baris ini. | M5: =Parameter!A6 -> Kafe / resto (F&B) | N5: =COUNTIFS($B$5:$B$104,M5,$I$5:$I$104,">0") -> 0 | O5: =IF(N5=0,"-",AVERAGEIFS($I$5:$I$104,$B$5:$B$104,M5,$I$5:$I$104,">0")) -> - | P5: =AVERAGE(Parameter!B6,Parameter!C6) -> 0.24
H6: =IF(OR(E6="",F6=""),"",E6*F6*12) | I6: =IF(OR(G6="",H6="",H6=0),"",G6/H6) | J6: =IF(OR(G6="",E6="",E6=0),"",G6/E6) | M6: =Parameter!A7 -> Fashion / aksesoris | N6: =COUNTIFS($B$5:$B$104,M6,$I$5:$I$104,">0") -> 0 | O6: =IF(N6=0,"-",AVERAGEIFS($I$5:$I$104,$B$5:$B$104,M6,$I$5:$I$104,">0")) -> - | P6: =AVERAGE(Parameter!B7,Parameter!C7) -> 0.275
H7: =IF(OR(E7="",F7=""),"",E7*F7*12) | I7: =IF(OR(G7="",H7="",H7=0),"",G7/H7) | J7: =IF(OR(G7="",E7="",E7=0),"",G7/E7) | M7: =Parameter!A8 -> Salon | N7: =COUNTIFS($B$5:$B$104,M7,$I$5:$I$104,">0") -> 0 | O7: =IF(N7=0,"-",AVERAGEIFS($I$5:$I$104,$B$5:$B$104,M7,$I$5:$I$104,">0")) -> - | P7: =AVERAGE(Parameter!B8,Parameter!C8) -> 0.275
H8: =IF(OR(E8="",F8=""),"",E8*F8*12) | I8: =IF(OR(G8="",H8="",H8=0),"",G8/H8) | J8: =IF(OR(G8="",E8="",E8=0),"",G8/E8) | M8: =Parameter!A9 -> Klinik kecantikan / kesehatan | N8: =COUNTIFS($B$5:$B$104,M8,$I$5:$I$104,">0") -> 0 | O8: =IF(N8=0,"-",AVERAGEIFS($I$5:$I$104,$B$5:$B$104,M8,$I$5:$I$104,">0")) -> - | P8: =AVERAGE(Parameter!B9,Parameter!C9) -> 0.275
H9: =IF(OR(E9="",F9=""),"",E9*F9*12) | I9: =IF(OR(G9="",H9="",H9=0),"",G9/H9) | J9: =IF(OR(G9="",E9="",E9=0),"",G9/E9) | M9: =Parameter!A10 -> Furnitur & dekorasi rumah (big-box) | N9: =COUNTIFS($B$5:$B$104,M9,$I$5:$I$104,">0") -> 0 | O9: =IF(N9=0,"-",AVERAGEIFS($I$5:$I$104,$B$5:$B$104,M9,$I$5:$I$104,">0")) -> - | P9: =AVERAGE(Parameter!B10,Parameter!C10) -> 0.13
H10: =IF(OR(E10="",F10=""),"",E10*F10*12) | I10: =IF(OR(G10="",H10="",H10=0),"",G10/H10) | J10: =IF(OR(G10="",E10="",E10=0),"",G10/E10) | M10: =Parameter!A11 -> Perlengkapan rumah & perkakas (big-box) | N10: =COUNTIFS($B$5:$B$104,M10,$I$5:$I$104,">0") -> 1 | O10: =IF(N10=0,"-",AVERAGEIFS($I$5:$I$104,$B$5:$B$104,M10,$I$5:$I$104,">0")) -> 0.10869565 | P10: =AVERAGE(Parameter!B11,Parameter!C11) -> 0.11
H11: =IF(OR(E11="",F11=""),"",E11*F11*12) | I11: =IF(OR(G11="",H11="",H11=0),"",G11/H11) | J11: =IF(OR(G11="",E11="",E11=0),"",G11/E11) | M11: =Parameter!A12 -> Apotek / toko kesehatan | N11: =COUNTIFS($B$5:$B$104,M11,$I$5:$I$104,">0") -> 0 | O11: =IF(N11=0,"-",AVERAGEIFS($I$5:$I$104,$B$5:$B$104,M11,$I$5:$I$104,">0")) -> - | P11: =AVERAGE(Parameter!B12,Parameter!C12) -> 0.06
H12: =IF(OR(E12="",F12=""),"",E12*F12*12) | I12: =IF(OR(G12="",H12="",H12=0),"",G12/H12) | J12: =IF(OR(G12="",E12="",E12=0),"",G12/E12) | M12: =Parameter!A13 -> Minimarket / grocery | N12: =COUNTIFS($B$5:$B$104,M12,$I$5:$I$104,">0") -> 0 | O12: =IF(N12=0,"-",AVERAGEIFS($I$5:$I$104,$B$5:$B$104,M12,$I$5:$I$104,">0")) -> - | P12: =AVERAGE(Parameter!B13,Parameter!C13) -> 0.055
H13: =IF(OR(E13="",F13=""),"",E13*F13*12) | I13: =IF(OR(G13="",H13="",H13=0),"",G13/H13) | J13: =IF(OR(G13="",E13="",E13=0),"",G13/E13) | M13: =Parameter!A14 -> Elektronik / gadget | N13: =COUNTIFS($B$5:$B$104,M13,$I$5:$I$104,">0") -> 0 | O13: =IF(N13=0,"-",AVERAGEIFS($I$5:$I$104,$B$5:$B$104,M13,$I$5:$I$104,">0")) -> - | P13: =AVERAGE(Parameter!B14,Parameter!C14) -> 0.065
H14: =IF(OR(E14="",F14=""),"",E14*F14*12) | I14: =IF(OR(G14="",H14="",H14=0),"",G14/H14) | J14: =IF(OR(G14="",E14="",E14=0),"",G14/E14)
H15: =IF(OR(E15="",F15=""),"",E15*F15*12) | I15: =IF(OR(G15="",H15="",H15=0),"",G15/H15) | J15: =IF(OR(G15="",E15="",E15=0),"",G15/E15) | M15: Jika sudah ada ≥3 proyek dalam satu kategori, salin "Rata-rata K Anda" ke sel K manual (Kalkulator!C15).
H16: =IF(OR(E16="",F16=""),"",E16*F16*12) | I16: =IF(OR(G16="",H16="",H16=0),"",G16/H16) | J16: =IF(OR(G16="",E16="",E16=0),"",G16/E16)
H17: =IF(OR(E17="",F17=""),"",E17*F17*12) | I17: =IF(OR(G17="",H17="",H17=0),"",G17/H17) | J17: =IF(OR(G17="",E17="",E17=0),"",G17/E17)
H18: =IF(OR(E18="",F18=""),"",E18*F18*12) | I18: =IF(OR(G18="",H18="",H18=0),"",G18/H18) | J18: =IF(OR(G18="",E18="",E18=0),"",G18/E18)
H19: =IF(OR(E19="",F19=""),"",E19*F19*12) | I19: =IF(OR(G19="",H19="",H19=0),"",G19/H19) | J19: =IF(OR(G19="",E19="",E19=0),"",G19/E19)
H20: =IF(OR(E20="",F20=""),"",E20*F20*12) | I20: =IF(OR(G20="",H20="",H20=0),"",G20/H20) | J20: =IF(OR(G20="",E20="",E20=0),"",G20/E20)
H21: =IF(OR(E21="",F21=""),"",E21*F21*12) | I21: =IF(OR(G21="",H21="",H21=0),"",G21/H21) | J21: =IF(OR(G21="",E21="",E21=0),"",G21/E21)
H22: =IF(OR(E22="",F22=""),"",E22*F22*12) | I22: =IF(OR(G22="",H22="",H22=0),"",G22/H22) | J22: =IF(OR(G22="",E22="",E22=0),"",G22/E22)
H23: =IF(OR(E23="",F23=""),"",E23*F23*12) | I23: =IF(OR(G23="",H23="",H23=0),"",G23/H23) | J23: =IF(OR(G23="",E23="",E23=0),"",G23/E23)
H24: =IF(OR(E24="",F24=""),"",E24*F24*12) | I24: =IF(OR(G24="",H24="",H24=0),"",G24/H24) | J24: =IF(OR(G24="",E24="",E24=0),"",G24/E24)
H25: =IF(OR(E25="",F25=""),"",E25*F25*12) | I25: =IF(OR(G25="",H25="",H25=0),"",G25/H25) | J25: =IF(OR(G25="",E25="",E25=0),"",G25/E25)
H26: =IF(OR(E26="",F26=""),"",E26*F26*12) | I26: =IF(OR(G26="",H26="",H26=0),"",G26/H26) | J26: =IF(OR(G26="",E26="",E26=0),"",G26/E26)
H27: =IF(OR(E27="",F27=""),"",E27*F27*12) | I27: =IF(OR(G27="",H27="",H27=0),"",G27/H27) | J27: =IF(OR(G27="",E27="",E27=0),"",G27/E27)
... H104: =IF(OR(E104="",F104=""),"",E104*F104*12) | I104: =IF(OR(G104="",H104="",H104=0),"",G104/H104) | J104: =IF(OR(G104="",E104="",E104=0),"",G104/E104)
